<mujoco model="qingyun_z1_A_rev_3_0">
  <compiler angle="radian" meshdir="../../../robolab/assets/QingYun_Robot_Description/qingyun_z1_A_rev_3_0_description/meshes/" />
  <default>
  <joint limited="true" armature="0.05"/>
  </default>
  <asset>
    <mesh name="base_link" file="base_link.STL" />
    <mesh name="rp_hip_pitch_link" file="rp_hip_pitch_link.STL" />
    <mesh name="rp_hip_roll_link" file="rp_hip_roll_link.STL" />
    <mesh name="rp_hip_yaw_link" file="rp_hip_yaw_link.STL" />
    <mesh name="rp_knee_pitch_link" file="rp_knee_pitch_link.STL" />
    <mesh name="rp_foot_pitch_link" file="rp_foot_pitch_link.STL" />
    <mesh name="lp_hip_pitch_link" file="lp_hip_pitch_link.STL" />
    <mesh name="lp_hip_roll_link" file="lp_hip_roll_link.STL" />
    <mesh name="lp_hip_yaw_link" file="lp_hip_yaw_link.STL" />
    <mesh name="lp_knee_pitch_link" file="lp_knee_pitch_link.STL" />
    <mesh name="lp_foot_pitch_link" file="lp_foot_pitch_link.STL" />
    <mesh name="p_torso_yaw_link" file="p_torso_yaw_link.STL" />
    <mesh name="rp_shoulder_pitch_link" file="rp_shoulder_pitch_link.STL" />
    <mesh name="rp_arm_roll_link" file="rp_arm_roll_link.STL" />
    <mesh name="rp_arm_yaw_link" file="rp_arm_yaw_link.STL" />
    <mesh name="rp_elbow_pitch_link" file="rp_elbow_pitch_link.STL" />
    <mesh name="lp_shoulder_pitch_link" file="lp_shoulder_pitch_link.STL" />
    <mesh name="lp_arm_roll_link" file="lp_arm_roll_link.STL" />
    <mesh name="lp_arm_yaw_link" file="lp_arm_yaw_link.STL" />
    <mesh name="lp_elbow_pitch_link" file="lp_elbow_pitch_link.STL" />
    <mesh name="p_neck_yaw_link" file="p_neck_yaw_link.STL" />
    <mesh name="p_necks_pitch_link" file="p_necks_pitch_link.STL" />
    <material name="base_link_mat" rgba="1 1 1 1" specular="0" />
    <material name="rp_hip_pitch_link_mat" rgba="1 1 1 1" specular="0" />
    <material name="rp_hip_roll_link_mat" rgba="1 1 1 1" specular="0" />
    <material name="rp_hip_yaw_link_mat" rgba="1 1 1 1" specular="0" />
    <material name="rp_knee_pitch_link_mat" rgba="1 1 1 1" specular="0" />
    <material name="rp_foot_pitch_link_mat" rgba="1 1 1 1" specular="0" />
    <material name="lp_hip_pitch_link_mat" rgba="1 1 1 1" specular="0" />
    <material name="lp_hip_roll_link_mat" rgba="1 1 1 1" specular="0" />
    <material name="lp_hip_yaw_link_mat" rgba="1 1 1 1" specular="0" />
    <material name="lp_knee_pitch_link_mat" rgba="1 1 1 1" specular="0" />
    <material name="lp_foot_pitch_link_mat" rgba="1 1 1 1" specular="0" />
    <material name="p_torso_yaw_link_mat" rgba="1 1 1 1" specular="0" />
    <material name="rp_shoulder_pitch_link_mat" rgba="1 1 1 1" specular="0" />
    <material name="rp_arm_roll_link_mat" rgba="1 1 1 1" specular="0" />
    <material name="rp_arm_yaw_link_mat" rgba="1 1 1 1" specular="0" />
    <material name="rp_elbow_pitch_link_mat" rgba="1 1 1 1" specular="0" />
    <material name="lp_shoulder_pitch_link_mat" rgba="1 1 1 1" specular="0" />
    <material name="lp_arm_roll_link_mat" rgba="1 1 1 1" specular="0" />
    <material name="lp_arm_yaw_link_mat" rgba="1 1 1 1" specular="0" />
    <material name="lp_elbow_pitch_link_mat" rgba="1 1 1 1" specular="0" />
    <material name="p_neck_yaw_link_mat" rgba="1 1 1 1" specular="0" />
    <material name="p_necks_pitch_link_mat" rgba="1 1 1 1" specular="0" />

    <texture type="2d" name="groundplane" builtin="checker" mark="edge" rgb1="0.2 0.3 0.4" rgb2="0.1 0.2 0.3" markrgb="0.8 0.8 0.8" width="300" height="300"/>
    <material name="groundplane" texture="groundplane" texuniform="true" texrepeat="5 5" reflectance="0.2"/>
  </asset>

  <worldbody>
    <light pos="0 0 3.5" dir="0 0 -1" directional="true"/>
    <geom name="floor" type="plane" pos="0 0 -0.6003" size="0 0 0.05" material="groundplane" friction="0.5 0.005 0.0001" condim="3"/>
    <body name="base_link" pos="0 0 0">
      <freejoint/>
      <inertial pos="-0.0000226 -0.00002 -0.0049416" mass="1.8" fullinertia="0.0014237 0.001136 0.0017497 -0.0000001 -0.0000005 0"/>
      <geom pos="0 0 0" group="1" contype="0" conaffinity="0" material="base_link_mat" type="mesh" mesh="base_link" />
      <geom pos="0 0 0" rgba="0.9373 0.2667 0.2667 1" group="3" contype="1" conaffinity="1" type="mesh" mesh="base_link" />
      <site name="imu" size="0.01" pos="0 0 0" />
      <body name="rp_hip_pitch_link" pos="-0.0000196 -0.05677 -0.043">
        <joint name="rw_hip_pitch_joint" type="hinge" axis="0 -1 0" limited="true" range="-1.3 1.3" damping="0" frictionloss="0"/>
        <inertial pos="-0.0061084 -0.038723 0.0000769" mass="0.48" fullinertia="0.0002478 0.0001734 0.0001852 -0.0000033 0.0000008 -0.0000004"/>
        <geom pos="0 0 0" group="1" contype="0" conaffinity="0" material="rp_hip_pitch_link_mat" type="mesh" mesh="rp_hip_pitch_link" />
        <geom pos="0 0 0" rgba="0.9373 0.2667 0.2667 1" group="3" contype="1" conaffinity="1" type="mesh" mesh="rp_hip_pitch_link" />
        <body name="rp_hip_roll_link" pos="0.016 -0.04 0">
          <joint name="rw_hip_roll_joint" type="hinge" axis="-1 0 0" limited="true" range="-0.35 0.7" damping="0" frictionloss="0"/>
          <inertial pos="-0.0003292 -0.0000059 -0.061621" mass="0.16871" fullinertia="0.0002361 0.0002396 0.0000458 0 0.0000395 0"/>
          <geom pos="0 0 0" group="1" contype="0" conaffinity="0" material="rp_hip_roll_link_mat" type="mesh" mesh="rp_hip_roll_link" />
          <geom pos="0 0 0" rgba="0.9373 0.2667 0.2667 1" group="3" contype="1" conaffinity="1" type="mesh" mesh="rp_hip_roll_link" />
          <body name="rp_hip_yaw_link" pos="-0.0206 0 -0.105">
            <joint name="rw_hip_yaw_joint" type="hinge" axis="0 0 -1" limited="true" range="-1 1" damping="0" frictionloss="0"/>
            <inertial pos="0.0004017 -0.0024637 -0.035119" mass="0.471" fullinertia="0.0001819 0.0001661 0.0002007 0.0000019 0.000001 0.0000153"/>
            <geom pos="0 0 0" group="1" contype="0" conaffinity="0" material="rp_hip_yaw_link_mat" type="mesh" mesh="rp_hip_yaw_link" />
            <geom pos="0 0 0" rgba="0.9373 0.2667 0.2667 1" group="3" contype="1" conaffinity="1" type="mesh" mesh="rp_hip_yaw_link" />
            <body name="rp_knee_pitch_link" pos="0 -0.02025 -0.1065">
              <joint name="rw_knee_pitch_joint" type="hinge" axis="0 -1 0" limited="true" range="-2 0" damping="0" frictionloss="0"/>
              <inertial pos="-0.0000246 0.020048 -0.096831" mass="1.16" fullinertia="0.0012845 0.0014053 0.0003474 0 0.0000009 0.000002"/>
              <geom pos="0 0 0" group="1" contype="0" conaffinity="0" material="rp_knee_pitch_link_mat" type="mesh" mesh="rp_knee_pitch_link" />
              <geom pos="0 0 0" rgba="0.9373 0.2667 0.2667 1" group="3" contype="1" conaffinity="1" type="mesh" mesh="rp_knee_pitch_link" />
              <body name="rp_foot_pitch_link" pos="0 0 -0.1934">
                <joint name="rw_foot_pitch_joint" type="hinge" axis="0 1 0" limited="true" range="-1 1.1" damping="0" frictionloss="0"/>
                <inertial pos="0.014063 0.016756 -0.051479" mass="0.52" fullinertia="0.0003208 0.0011075 0.0012327 0.0000036 -0.000012 -0.0000439"/>
                <geom pos="0 0 0" group="1" contype="0" conaffinity="0" material="rp_foot_pitch_link_mat" type="mesh" mesh="rp_foot_pitch_link" />
                <geom pos="0.017 0.025 -0.077" rgba="0.9373 0.2667 0.2667 1" group="3" contype="1" conaffinity="1" type="box" size="0.085 0.035 0.004" />
              </body>
            </body>
          </body>
        </body>
      </body>
      <body name="lp_hip_pitch_link" pos="-0.0000196 0.05673 -0.043253">
        <joint name="lw_hip_pitch_joint" type="hinge" axis="0 1 0" limited="true" range="-1.3 1.3" damping="0" frictionloss="0"/>
        <inertial pos="-0.0022142 0.036977 0.0004552" mass="0.48" fullinertia="0.0003049 0.0001961 0.000224 0.0000076 0.0000018 0.0000011"/>
        <geom pos="0 0 0" group="1" contype="0" conaffinity="0" material="lp_hip_pitch_link_mat" type="mesh" mesh="lp_hip_pitch_link" />
        <geom pos="0 0 0" rgba="0.9373 0.2667 0.2667 1" group="3" contype="1" conaffinity="1" type="mesh" mesh="lp_hip_pitch_link" />
        <body name="lp_hip_roll_link" pos="0.016 0.04 0.0002528">
          <joint name="lw_hip_roll_joint" type="hinge" axis="-1 0 0" limited="true" range="-0.7 0.35" damping="0" frictionloss="0"/>
          <inertial pos="-0.0003292 0.0000059 -0.061621" mass="0.16871" fullinertia="0.0002361 0.0002396 0.0000458 0 0.0000395 0"/>
          <geom pos="0 0 0" group="1" contype="0" conaffinity="0" material="lp_hip_roll_link_mat" type="mesh" mesh="lp_hip_roll_link" />
          <geom pos="0 0 0" rgba="0.9373 0.2667 0.2667 1" group="3" contype="1" conaffinity="1" type="mesh" mesh="lp_hip_roll_link" />
          <body name="lp_hip_yaw_link" pos="-0.0206 0 -0.105">
            <joint name="lw_hip_yaw_joint" type="hinge" axis="0 0 -1" limited="true" range="-1 1" damping="0" frictionloss="0"/>
            <inertial pos="0.0008769 0.0057873 -0.048588" mass="0.471" fullinertia="0.0002202 0.0001838 0.0002007 -0.0000044 0.0000024 -0.0000357"/>
            <geom pos="0 0 0" group="1" contype="0" conaffinity="0" material="lp_hip_yaw_link_mat" type="mesh" mesh="lp_hip_yaw_link" />
            <geom pos="0 0 0" rgba="0.9373 0.2667 0.2667 1" group="3" contype="1" conaffinity="1" type="mesh" mesh="lp_hip_yaw_link" />
            <body name="lp_knee_pitch_link" pos="0 0.02025 -0.1065">
              <joint name="lw_knee_pitch_joint" type="hinge" axis="0 1 0" limited="true" range="0 2" damping="0" frictionloss="0"/>
              <inertial pos="-0.0000056 -0.015691 -0.096928" mass="1.16" fullinertia="0.0020726 0.0021969 0.000322 0.0000002 0.0000016 -0.0000039"/>
              <geom pos="0 0 0" group="1" contype="0" conaffinity="0" material="lp_knee_pitch_link_mat" type="mesh" mesh="lp_knee_pitch_link" />
              <geom pos="0 0 0" rgba="0.9373 0.2667 0.2667 1" group="3" contype="1" conaffinity="1" type="mesh" mesh="lp_knee_pitch_link" />
              <body name="lp_foot_pitch_link" pos="0 0 -0.1934">
                <joint name="lw_foot_pitch_joint" type="hinge" axis="0 -1 0" limited="true" range="-1.1 1" damping="0" frictionloss="0"/>
                <inertial pos="0.014045 -0.016802 -0.051649" mass="0.52" fullinertia="0.0003163 0.0011016 0.0012275 -0.0000032 -0.0000113 0.0000425"/>
                <geom pos="0 0 0" group="1" contype="0" conaffinity="0" material="lp_foot_pitch_link_mat" type="mesh" mesh="lp_foot_pitch_link" />
                <geom pos="0.017 -0.025 -0.077" rgba="0.9373 0.2667 0.2667 1" group="3" contype="1" conaffinity="1" type="box" size="0.085 0.035 0.004" />
              </body>
            </body>
          </body>
        </body>
      </body>
      <body name="p_torso_yaw_link" pos="-0.0000196 -0.0000196 0.052">
        <joint name="waist_yaw_joint" type="hinge" axis="0 0 -1" limited="true" range="-1 1" damping="0" frictionloss="0"/>
        <inertial pos="0.0005574 0.0000005 0.14472" mass="5.5" fullinertia="0.0151319 0.0130694 0.0054201 -0.0000001 -0.0000002 0"/>
        <geom pos="0 0 0" group="1" contype="0" conaffinity="0" material="p_torso_yaw_link_mat" type="mesh" mesh="p_torso_yaw_link" />
        <geom pos="0 0 0" rgba="0.9373 0.2667 0.2667 1" group="3" contype="1" conaffinity="1" type="mesh" mesh="p_torso_yaw_link" />
        <body name="rp_shoulder_pitch_link" pos="0.002 -0.1219 0.2105">
          <joint name="rw_shoulder_pitch_joint" type="hinge" axis="0 -1 0" limited="true" range="-1 1" damping="0" frictionloss="0"/>
          <inertial pos="-0.0044047 -0.037055 0.0000339" mass="0.41" fullinertia="0.0002491 0.0001849 0.0002093 -0.0000054 0.0000002 0"/>
          <geom pos="0 0 0" group="1" contype="0" conaffinity="0" material="rp_shoulder_pitch_link_mat" type="mesh" mesh="rp_shoulder_pitch_link" />
          <geom pos="0 0 0" rgba="0.9373 0.2667 0.2667 1" group="3" contype="1" conaffinity="1" type="mesh" mesh="rp_shoulder_pitch_link" />
          <body name="rp_arm_roll_link" pos="0.01465 -0.04 0">
            <joint name="rw_arm_roll_joint" type="hinge" axis="1 0 0" limited="true" range="-1.6 0.27" damping="0" frictionloss="0"/>
            <inertial pos="0.0009329 0.0000144 -0.021784" mass="0.068221" fullinertia="0.0000278 0.0000296 0.0000164 0 0.0000064 0"/>
            <geom pos="0 0 0" group="1" contype="0" conaffinity="0" material="rp_arm_roll_link_mat" type="mesh" mesh="rp_arm_roll_link" />
            <geom pos="0 0 0" rgba="0.9373 0.2667 0.2667 1" group="3" contype="1" conaffinity="1" type="mesh" mesh="rp_arm_roll_link" />
            <body name="rp_arm_yaw_link" pos="-0.01465 0 -0.0425">
              <joint name="rw_arm_yaw_joint" type="hinge" axis="0 0 1" limited="true" range="-1 1" damping="0" frictionloss="0"/>
              <inertial pos="0.0000216 -0.0081596 -0.06335" mass="0.581" fullinertia="0.0002698 0.0002866 0.0001789 0.0000002 0 0.0000551"/>
              <geom pos="0 0 0" group="1" contype="0" conaffinity="0" material="rp_arm_yaw_link_mat" type="mesh" mesh="rp_arm_yaw_link" />
              <geom pos="0 0 0" rgba="0.9373 0.2667 0.2667 1" group="3" contype="1" conaffinity="1" type="mesh" mesh="rp_arm_yaw_link" />
              <body name="rp_elbow_pitch_link" pos="0 0.025 -0.095">
                <joint name="rw_elbow_pitch_joint" type="hinge" axis="0 -1 0" limited="true" range="-1.57 1.57" damping="0" frictionloss="0"/>
                <inertial pos="0 -0.0026494 -0.03996" mass="0.079289" fullinertia="0.0000695 0.0000623 0.0000251 0 0 0.0000151"/>
                <geom pos="0 0 0" group="1" contype="0" conaffinity="0" material="rp_elbow_pitch_link_mat" type="mesh" mesh="rp_elbow_pitch_link" />
                <geom pos="0 0 0" rgba="0.9373 0.2667 0.2667 1" group="3" contype="1" conaffinity="1" type="mesh" mesh="rp_elbow_pitch_link" />
              </body>
            </body>
          </body>
        </body>
        <body name="lp_shoulder_pitch_link" pos="0.002 0.1219 0.2105">
          <joint name="lw_shoulder_pitch_joint" type="hinge" axis="0 1 0" limited="true" range="-1 1" damping="0" frictionloss="0"/>
          <inertial pos="-0.0076396 0.038405 0.0000183" mass="0.41" fullinertia="0.0002112 0.0001779 0.0001915 0.000003 0.0000001 0"/>
          <geom pos="0 0 0" group="1" contype="0" conaffinity="0" material="lp_shoulder_pitch_link_mat" type="mesh" mesh="lp_shoulder_pitch_link" />
          <geom pos="0 0 0" rgba="0.9373 0.2667 0.2667 1" group="3" contype="1" conaffinity="1" type="mesh" mesh="lp_shoulder_pitch_link" />
          <body name="lp_arm_roll_link" pos="0.01465 0.04 0">
            <joint name="lw_arm_roll_joint" type="hinge" axis="1 0 0" limited="true" range="-0.27 1.6" damping="0" frictionloss="0"/>
            <inertial pos="0.0009329 -0.0000146 -0.021784" mass="0.068221" fullinertia="0.0000278 0.0000296 0.0000164 0 0.0000064 0"/>
            <geom pos="0 0 0" group="1" contype="0" conaffinity="0" material="lp_arm_roll_link_mat" type="mesh" mesh="lp_arm_roll_link" />
            <geom pos="0 0 0" rgba="0.9373 0.2667 0.2667 1" group="3" contype="1" conaffinity="1" type="mesh" mesh="lp_arm_roll_link" />
            <body name="lp_arm_yaw_link" pos="-0.01465 0 -0.0425">
              <joint name="lw_arm_yaw_joint" type="hinge" axis="0 0 1" limited="true" range="-1 1" damping="0" frictionloss="0"/>
              <inertial pos="0.0000485 -0.0005801 -0.058605" mass="0.581" fullinertia="0.0001579 0.0001903 0.0001615 -0.0000005 0 -0.0000151"/>
              <geom pos="0 0 0" group="1" contype="0" conaffinity="0" material="lp_arm_yaw_link_mat" type="mesh" mesh="lp_arm_yaw_link" />
              <geom pos="0 0 0" rgba="0.9373 0.2667 0.2667 1" group="3" contype="1" conaffinity="1" type="mesh" mesh="lp_arm_yaw_link" />
              <body name="lp_elbow_pitch_link" pos="0 -0.025 -0.095">
                <joint name="lw_elbow_pitch_joint" type="hinge" axis="0 1 0" limited="true" range="-1.57 1" damping="0" frictionloss="0"/>
                <inertial pos="0 0.0026494 -0.03996" mass="0.079289" fullinertia="0.0000695 0.0000623 0.0000251 0 0 -0.0000151"/>
                <geom pos="0 0 0" group="1" contype="0" conaffinity="0" material="lp_elbow_pitch_link_mat" type="mesh" mesh="lp_elbow_pitch_link" />
                <geom pos="0 0 0" rgba="0.9373 0.2667 0.2667 1" group="3" contype="1" conaffinity="1" type="mesh" mesh="lp_elbow_pitch_link" />
              </body>
            </body>
          </body>
        </body>
        <body name="p_neck_yaw_link" pos="0.002 0 0.239">
          <inertial pos="0.0003763 -0.0023684 0.023971" mass="0.3" fullinertia="0.0000986 0.000093 0.0001151 0.0000023 0.0000023 -0.0000054"/>
          <geom pos="0 0 0" group="1" contype="0" conaffinity="0" material="p_neck_yaw_link_mat" type="mesh" mesh="p_neck_yaw_link" />
          <geom pos="0 0 0" rgba="0.9373 0.2667 0.2667 1" group="3" contype="1" conaffinity="1" type="mesh" mesh="p_neck_yaw_link" />
          <body name="p_necks_pitch_link" pos="0 -0.021139 0.038872">
            <inertial pos="0.0011538 0.016367 0.026134" mass="0.185" fullinertia="0.0003051 0.0003245 0.0004944 0.0000005 0.000002 0.0000037"/>
            <geom pos="0 0 0" group="1" contype="0" conaffinity="0" material="p_necks_pitch_link_mat" type="mesh" mesh="p_necks_pitch_link" />
            <geom pos="0 0 0" rgba="0.9373 0.2667 0.2667 1" group="3" contype="1" conaffinity="1" type="mesh" mesh="p_necks_pitch_link" />
          </body>
        </body>
      </body>
    </body>
  </worldbody>
  <actuator>
    <motor name="rw_hip_pitch_joint_motor" joint="rw_hip_pitch_joint" gear="1" ctrllimited="true" ctrlrange="-120 120" />
    <motor name="rw_hip_roll_joint_motor" joint="rw_hip_roll_joint" gear="1" ctrllimited="true" ctrlrange="-27 27" />
    <motor name="rw_hip_yaw_joint_motor" joint="rw_hip_yaw_joint" gear="1" ctrllimited="true" ctrlrange="-27 27" />
    <motor name="rw_knee_pitch_joint_motor" joint="rw_knee_pitch_joint" gear="1" ctrllimited="true" ctrlrange="-120 120" />
    <motor name="rw_foot_pitch_joint_motor" joint="rw_foot_pitch_joint" gear="1" ctrllimited="true" ctrlrange="-27 27" />
    <motor name="lw_hip_pitch_joint_motor" joint="lw_hip_pitch_joint" gear="1" ctrllimited="true" ctrlrange="-120 120" />
    <motor name="lw_hip_roll_joint_motor" joint="lw_hip_roll_joint" gear="1" ctrllimited="true" ctrlrange="-27 27" />
    <motor name="lw_hip_yaw_joint_motor" joint="lw_hip_yaw_joint" gear="1" ctrllimited="true" ctrlrange="-27 27" />
    <motor name="lw_knee_pitch_joint_motor" joint="lw_knee_pitch_joint" gear="1" ctrllimited="true" ctrlrange="-120 120" />
    <motor name="lw_foot_pitch_joint_motor" joint="lw_foot_pitch_joint" gear="1" ctrllimited="true" ctrlrange="-27 27" />
    <motor name="waist_yaw_joint_motor" joint="waist_yaw_joint" gear="1" ctrllimited="true" ctrlrange="-17 17" />
    <motor name="rw_shoulder_pitch_joint_motor" joint="rw_shoulder_pitch_joint" gear="1" ctrllimited="true" ctrlrange="-6 6" />
    <motor name="rw_arm_roll_joint_motor" joint="rw_arm_roll_joint" gear="1" ctrllimited="true" ctrlrange="-6 6" />
    <motor name="rw_arm_yaw_joint_motor" joint="rw_arm_yaw_joint" gear="1" ctrllimited="true" ctrlrange="-6 6" />
    <motor name="rw_elbow_pitch_joint_motor" joint="rw_elbow_pitch_joint" gear="1" ctrllimited="true" ctrlrange="-6 6" />
    <motor name="lw_shoulder_pitch_joint_motor" joint="lw_shoulder_pitch_joint" gear="1" ctrllimited="true" ctrlrange="-6 6" />
    <motor name="lw_arm_roll_joint_motor" joint="lw_arm_roll_joint" gear="1" ctrllimited="true" ctrlrange="-6 6" />
    <motor name="lw_arm_yaw_joint_motor" joint="lw_arm_yaw_joint" gear="1" ctrllimited="true" ctrlrange="-6 6" />
    <motor name="lw_elbow_pitch_joint_motor" joint="lw_elbow_pitch_joint" gear="1" ctrllimited="true" ctrlrange="-6 6" />
  </actuator>
  <sensor>
    <framequat name="orientation" objtype="site" noise="0.001" objname="imu" />
    <framepos name="position" objtype="site" noise="0.001" objname="imu" />
    <gyro name="angular-velocity" site="imu" noise="0.005" cutoff="34.9" />
    <velocimeter name="linear-velocity" site="imu" noise="0.001" cutoff="30" />
    <accelerometer name="linear-acceleration" site="imu" noise="0.005" cutoff="157" />
    <magnetometer name="magnetometer" site="imu" />
  </sensor>
  <visual>
    <global offwidth="1920" offheight="1080" />
  </visual>
</mujoco>
